Workbook

Sheet 未翻译专辑
A1: 序号 | B1: 英文 Key | C1: 作品数 | D1: 翻译后名称（请手动填写） | E1: 备注
A2: 1 | B2: ai generated | C2: 115 | D2: ai生成
A3: 2 | B3: alp | C3: 65 | D3: alp
A4: 3 | B4: toratora | C4: 52 | D4: toratora
A5: 4 | B5: drachef | C5: 31 | D5: =_xlfn.XLOOKUP(B5,Sheet1!B:B,Sheet1!C:C,"无") -> 龙F (Drache)
A6: 5 | B6: ankoman | C6: 27 | D6: =_xlfn.XLOOKUP(B6,Sheet1!B:B,Sheet1!C:C,"无") -> 馅饼人 / 杏子人
A7: 6 | B7: chilt | C7: 19 | D7: =_xlfn.XLOOKUP(B7,Sheet1!B:B,Sheet1!C:C,"无") -> Chilt
A8: 7 | B8: syunichi | C8: 18 | D8: =_xlfn.XLOOKUP(B8,Sheet1!B:B,Sheet1!C:C,"无") -> 俊一
A9: 8 | B9: poper | C9: 17 | D9: =_xlfn.XLOOKUP(B9,Sheet1!B:B,Sheet1!C:C,"无") -> Poper
A10: 9 | B10: remu | C10: 16 | D10: remu
A11: 10 | B11: liyoosa | C11: 14 | D11: =_xlfn.XLOOKUP(B11,Sheet1!B:B,Sheet1!C:C,"无") -> Liyoosa
A12: 11 | B12: 38 | C12: 10 | D12: 38
A13: 12 | B13: enokido | C13: 10 | D13: =_xlfn.XLOOKUP(B13,Sheet1!B:B,Sheet1!C:C,"无") -> 榎户
A14: 13 | B14: ie | C14: 10 | D14: ie
A15: 14 | B15: konoshige | C15: 10 | D15: =_xlfn.XLOOKUP(B15,Sheet1!B:B,Sheet1!C:C,"无") -> 此重
A16: 15 | B16: airandou | C16: 9 | D16: =_xlfn.XLOOKUP(B16,Sheet1!B:B,Sheet1!C:C,"无") -> 爱兰堂
A17: 16 | B17: maskwolf | C17: 8 | D17: =_xlfn.XLOOKUP(B17,Sheet1!B:B,Sheet1!C:C,"无") -> 面具狼
A18: 17 | B18: anon 2-okunen | C18: 7 | D18: =_xlfn.XLOOKUP(B18,Sheet1!B:B,Sheet1!C:C,"无") -> 匿名2亿年
A19: 18 | B19: chae | C19: 7 | D19: =_xlfn.XLOOKUP(B19,Sheet1!B:B,Sheet1!C:C,"无") -> Chae
A20: 19 | B20: kurukuru | C20: 7 | D20: =_xlfn.XLOOKUP(B20,Sheet1!B:B,Sheet1!C:C,"无") -> Kurukuru
A21: 20 | B21: f.w.zholic | C21: 6 | D21: f.w.zholic
A22: 21 | B22: rapscallion | C22: 6 | D22: =_xlfn.XLOOKUP(B22,Sheet1!B:B,Sheet1!C:C,"无") -> Rapscallion
A23: 22 | B23: cherachera | C23: 5 | D23: =_xlfn.XLOOKUP(B23,Sheet1!B:B,Sheet1!C:C,"无") -> Cherachera
A24: 23 | B24: jils | C24: 5 | D24: =_xlfn.XLOOKUP(B24,Sheet1!B:B,Sheet1!C:C,"无") -> Jils
A25: 24 | B25: nyangboob | C25: 5 | D25: =_xlfn.XLOOKUP(B25,Sheet1!B:B,Sheet1!C:C,"无") -> Nyangboob
A26: 25 | B26: jewel | C26: 4 | D26: =_xlfn.XLOOKUP(B26,Sheet1!B:B,Sheet1!C:C,"无") -> Jewel
A27: 26 | B27: shiromitsu | C27: 4 | D27: =_xlfn.XLOOKUP(B27,Sheet1!B:B,Sheet1!C:C,"无") -> 白蜜
A28: 27 | B28: sleep-zzz | C28: 4 | D28: =_xlfn.XLOOKUP(B28,Sheet1!B:B,Sheet1!C:C,"无") -> Sleep-zzz
A29: 28 | B29: tsubaki aruo | C29: 4 | D29: =_xlfn.XLOOKUP(B29,Sheet1!B:B,Sheet1!C:C,"无") -> 椿有绪
A30: 29 | B30: grimgrim | C30: 3 | D30: grimgrim
A31: 30 | B31: maruco | C31: 3 | D31: =_xlfn.XLOOKUP(B31,Sheet1!B:B,Sheet1!C:C,"无") -> Maruco
A32: 31 | B32: miyu | C32: 3 | D32: =_xlfn.XLOOKUP(B32,Sheet1!B:B,Sheet1!C:C,"无") -> Miyu
A33: 32 | B33: nemu | C33: 3 | D33: =_xlfn.XLOOKUP(B33,Sheet1!B:B,Sheet1!C:C,"无") -> Nemu
A34: 33 | B34: akaneiro | C34: 2 | D34: =_xlfn.XLOOKUP(B34,Sheet1!B:B,Sheet1!C:C,"无") -> 茜色
A35: 34 | B35: asakura kukuri | C35: 2 | D35: =_xlfn.XLOOKUP(B35,Sheet1!B:B,Sheet1!C:C,"无") -> 朝仓括
A36: 35 | B36: brave chicken | C36: 2 | D36: =_xlfn.XLOOKUP(B36,Sheet1!B:B,Sheet1!C:C,"无") -> 勇者鸡
A37: 36 | B37: great mosu | C37: 2 | D37: =_xlfn.XLOOKUP(B37,Sheet1!B:B,Sheet1!C:C,"无") -> 大摩斯
A38: 37 | B38: hourai nepenthes | C38: 2 | D38: =_xlfn.XLOOKUP(B38,Sheet1!B:B,Sheet1!C:C,"无") -> 蓬莱猪笼草
A39: 38 | B39: kurakino issiki | C39: 2 | D39: =_xlfn.XLOOKUP(B39,Sheet1!B:B,Sheet1!C:C,"无") -> 藏野一色
A40: 39 | B40: maitake | C40: 2 | D40: =_xlfn.XLOOKUP(B40,Sheet1!B:B,Sheet1!C:C,"无") -> 舞茸
...

Sheet Sheet1
A1: 序号 | B1: 英文 Key | C1: 翻译后名称
A2: 4 | B2: drachef | C2: 龙F (Drache)
A3: 5 | B3: ankoman | C3: 馅饼人 / 杏子人
A4: 6 | B4: chilt | C4: Chilt
A5: 7 | B5: syunichi | C5: 俊一
A6: 8 | B6: poper | C6: Poper
A7: 10 | B7: liyoosa | C7: Liyoosa
A8: 12 | B8: enokido | C8: 榎户
A9: 14 | B9: konoshige | C9: 此重
A10: 15 | B10: airandou | C10: 爱兰堂
A11: 16 | B11: maskwolf | C11: 面具狼
A12: 17 | B12: anon 2-okunen | C12: 匿名2亿年
A13: 18 | B13: chae | C13: Chae
... A139: 148 | B139: yakisobapantarou | C139: 炒面太郎

Sheet 说明
A1: 使用说明
A3: 1. 颜色含义
A4: 红色背景 | B4: 作品数 >= 10（大量作品，优先翻译）
A5: 橙色背景 | B5: 作品数 3-9（中等数量）
A6: 绿色背景 | B6: 作品数 1-2（少量作品）
A7: 黄色背景 | B7: 翻译后名称列，手动填写区域
A9: 2. 填写方式
B10: 在"翻译后名称"列填入对应中文名
B11: 留空的行将被跳过，不会更新数据库
B12: 填写完成后告诉我，我会批量更新 album_config 表
A14: 3. 自动排除
B15: 以下 Key 本身已是中文，已自动排除：
B16: 挂乌冬面(1部)、无名小卒(3部)、波浦(1部)、青葵堂(1部)
A18: 4. 统计
B19: 共 148 个未翻译专辑
B20: 已翻译 56 个专辑（Key != Name）
B21: 中文 Key 4 个（无需翻译）
A23: 5. 翻译建议
B24: 日文罗马字作者名可查 E-Hentai 标签获取日文原名再翻译
B25: 纯英文名可音译或意译（如 maskwolf -> 面具狼）
B26: 不确定的名称可留空
